Workbook

Sheet SidekickCapTable
H2: Current
B3: Shareholder | C3: Founders CS | D3: RSA | E3: Options | F3: Exercised Options | G3: Total | H3: % FDS
B4: Brian Hazzard | C4: 3600000 | G4: =SUM(C4:F4) -> 3600000 | H4: =G4/$G$23 -> 0.36959988
B5: David Wolpoff | C5: 3600000 | G5: =SUM(C5:F5) -> 3600000 | H5: =G5/$G$23 -> 0.36959988
B6: Ian Lee | C6: 222187 | G6: =SUM(C6:F6) -> 222187 | H6: =G6/$G$23 -> 0.022811191
B7: Kyle Haugsness | C7: 592500 | G7: =SUM(C7:F7) -> 592500 | H7: =G7/$G$23 -> 0.06082998
B8: Paul Riegle | C8: 592500 | G8: =SUM(C8:F8) -> 592500 | H8: =G8/$G$23 -> 0.06082998
B9: Chris Butts | C9: 13500 | D9: 98900 | G9: =SUM(C9:F9) -> 112400 | H9: =G9/$G$23 -> 0.011539729
B10: Maurice Granfield | C10: 9000 | G10: =SUM(C10:F10) -> 9000 | H10: =G10/$G$23 -> 0.00092399969
B11: Pawan Lakshmanan | D11: 95000 | G11: =SUM(C11:F11) -> 95000 | H11: =G11/$G$23 -> 0.0097533301
B12: Matthew Howe | E12: 25000 | G12: =SUM(C12:F12) -> 25000 | H12: =G12/$G$23 -> 0.0025666658
B13: Andrew Ethan Boyce-Lewis | E13: 41562 | G13: =SUM(C13:F13) -> 41562 | H13: =G13/$G$23 -> 0.0042670306
B14: Eric McIntyre | D14: 285000 | G14: =SUM(C14:F14) -> 285000 | H14: =G14/$G$23 -> 0.02925999
B15: Patrick Heath | D15: 50000 | G15: =SUM(C15:F15) -> 50000 | H15: =G15/$G$23 -> 0.0051333316
B16: Chris Lord | D16: 285000 | G16: =SUM(C16:F16) -> 285000 | H16: =G16/$G$23 -> 0.02925999
B17: Eric Freedman | E17: 96186 | G17: =SUM(C17:F17) -> 96186 | H17: =G17/$G$23 -> 0.0098750927
B18: Miguel Bollar | E18: 48095 | G18: =SUM(C18:F18) -> 48095 | H18: =G18/$G$23 -> 0.0049377517
B19: Bradly Matheson | F19: 12395 | G19: =SUM(C19:F19) -> 12395 | H19: =G19/$G$23 -> 0.0012725529
B20: Cole Proctor | F20: 8333 | G20: =SUM(C20:F20) -> 8333 | H20: =G20/$G$23 -> 0.00085552105
B21: Available Options | D21: 65105 | G21: =SUM(C21:F21) -> 65105 | H21: =G21/$G$23 -> 0.0066841111
B23: Total | C23: =SUM(C4:C21) -> 8629687 | D23: =SUM(D4:D21) -> 879005 | E23: =SUM(E4:E21) -> 210843 | F23: =SUM(F4:F21) -> 20728 | G23: =SUM(G4:G21) -> 9740263
B26: SAFE Investments
B27: Shareholder | C27: SAFE | E27: Notes
B28: Chris Butts | C28: 25000 | E28: IRA is actual investor
B29: Maurice Granfield | C29: 25000
B30: Accomplice Founder Fund, L.P. | C30: 137170.75
B31: Accomplice Fund IV, L.P | C31: 3846829.2
B32: Amir Bagherzadeh | C32: 16566 | E32: Transfer from Owl Rocl Capital II, LLC (Accomplice)
B33: Elizabeth A. Donaghey Irrevocable Trust 2016 | C33: 250000
B34: Gunderson Partners | C34: 100000
B35: Joe Arcadi | C35: 300000 | E35: IRA is actual investor
B36: Kamal Ravikant Capital, LP - E4 | C36: 37500 | E36: Navel
B37: Maria Cirino | C37: 250000
B38: Mike Viscuso | C38: 100000
B39: Mozart Holdings, LLC | C39: 41164 | E39: Transfer from Owl Rocl Capital II, LLC (Accomplice)
B40: Orcinus Generational Irrevocable Trust - 2024 | C40: 2328778 | E40: Transfer from Owl Rocl Capital II, LLC (Accomplice)
B41: Owl Rock Capital III, LLC | C41: 1506000 | E41: Accomplice
B42: Ralph Folz | C42: 50000
B43: Ravikant Capital, LP - F3 | C43: 212500 | E43: Navel
B44: Sean Leach | C44: 25000
...

Sheet Inputs
B1: Sidekick (Think More Security, Inc.)
B2: Investment Model Inputs
B4: Series A Assumptions
B5: Pre-Money Valuation | C5: 60000000
B6: Total Series A Raise | C6: 20000000
B7: 1011 Ventures Investment | C7: 12000000
B8: Accomplice Investment | C8: 5000000
B9: Other Series A Investors | C9: 3000000
B10: Check: Total = Sum of investors | C10: =C6-(C7+C8+C9) -> 0
B12: SAFE Conversion
B13: SAFE Post-Money Valuation Cap | C13: 50000000
B15: Series A Option Pool
B16: Option Pool Target (% of post-A FD) | C16: 0.1
B18: Series B Assumptions
B19: Pre-Money Valuation | C19: 150000000
B20: Total Series B Raise | C20: 30000000
B21: New Other Series B Investors | C21: 15000000
B22: Pro-Rata Participant Tranche | C22: 15000000
B23: Series B Option Pool Gross Top-Up (% of post-B FD) | C23: 0.07
B25: Waterfall Assumptions
B26: Transaction Expense Rate | C26: 0.015
B27: Management Carveout Rate | C27: 0.1
B29: Key Dates
B30: 1011 Ventures First Investment Date (Series A Close) | C30: 46174
B31: Series B Close Date | C31: =DATE(YEAR(C30)+1,MONTH(C30)+6,DAY(C30)) -> 46722
B32: Assumed Exit Date (Post-A) | C32: =DATE(YEAR(C30)+5,MONTH(C30),DAY(C30)) -> 48000
B33: Assumed Exit Date (Post-B) | C33: =DATE(YEAR(C31)+3,MONTH(C31),DAY(C31)) -> 47818

Sheet SeriesA
B1: SIDEKICK & 1011 VENTURES SERIES A
C4: Common | D4: Safe Preferred | G4: Option | I4: Series A Preferred | L4: Option | N4: Total Capitalization
C5: # of | D5: $ | E5: Safe Pref | G5: Pool + | I5: $ | J5: Series A | L5: Pool + | N5: Total FD | O5: %
C6: Shares | D6: Invested | E6: Shares | G6: Pre A | I6: Invested | J6: Shares | L6: Pre A | N6: Shares | O6: FD
B7: Common Stock and Options:
B8: Brian Hazzard | C8: =SidekickCapTable!C4 -> 3600000 | N8: =C8+E8+G8+J8 -> 3600000 | O8: =N8/$N$20 -> 0.20126781
B9: David Wolpoff | C9: =SidekickCapTable!C5 -> 3600000 | N9: =C9+E9+G9+J9 -> 3600000 | O9: =N9/$N$20 -> 0.20126781
B10: Other Common Shareholders | C10: =SUM(SidekickCapTable!C6:C10) -> 1429687 | N10: =C10+E10+G10+J10 -> 1429687 | O10: =N10/$N$20 -> 0.079930549
B11: ESOP Issued and Outstanding | C11: =SUM(SidekickCapTable!D4:D21,SidekickCapTable!E4:E21,SidekickCapTable!F4:F21)-SidekickCapTable!D21 -> 1045471 | N11: =C11+E11+G11+J11 -> 1045471 | O11: =N11/$N$20 -> 0.058449906
B12: ESOP Available | C12: =SidekickCapTable!D21 -> 65105 | G12: =Inputs!C16*N20-C12 -> 1723556.6 | N12: =C12+G12 -> 1788661.6 | O12: =N12/$N$20 -> 0.1
B13: Total Common | C13: =SUM(C8:C12) -> 9740263 | G13: =G12 -> 1723556.6 | N13: =SUM(N8:N12) -> 11463820 | O13: =N13/$N$20 -> 0.64091608
B15: Preferred Rounds
B16: Accomplice | D16: =SUM(SidekickCapTable!C30,SidekickCapTable!C31,SidekickCapTable!C32,SidekickCapTable!C39,SidekickCapTable!C40,SidekickCapTable!C41,SidekickCapTable!C45,SidekickCapTable!C48) -> 8000000 | E16: =IFERROR(ROUND(D16/N23,0),0) -> 1939567 | I16: =Inputs!C8 -> 5000000 | J16: =IFERROR(ROUND(I16/N24,0),0) -> 1010191 | N16: =C16+E16+J16 -> 2949758 | O16: =N16/$N$20 -> 0.16491426
B17: Other SAFE Investors | D17: =SUM(SidekickCapTable!C28,SidekickCapTable!C29,SidekickCapTable!C33,SidekickCapTable!C34,SidekickCapTable!C35,SidekickCapTable!C36,SidekickCapTable!C37,SidekickCapTable!C38,SidekickCapTable!C42,SidekickCapTable!C43,SidekickCapTable!C44,SidekickCapTable!C46,SidekickCapTable!C47,SidekickCapTable!C49) -> 1825000 | E17: =IFERROR(ROUND(D17/N23,0),0) -> 442464 | N17: =C17+E17+J17 -> 442464 | O17: =N17/$N$20 -> 0.024737156
B18: 1011 Ventures | I18: =Inputs!C7 -> 12000000 | J18: =IFERROR(ROUND(I18/N24,0),0) -> 2424459 | N18: =C18+E18+J18 -> 2424459 | O18: =N18/$N$20 -> 0.13554599
B19: Other Series A Investors | I19: =Inputs!C9 -> 3000000 | J19: =IFERROR(ROUND(I19/N24,0),0) -> 606115 | N19: =C19+E19+J19 -> 606115 | O19: =N19/$N$20 -> 0.033886511
B20: Totals | C20: =C13+SUM(C16:C19) -> 9740263 | D20: =SUM(D16:D19) -> 9825000 | E20: =SUM(E16:E19) -> 2382031 | G20: =G13 -> 1723556.6 | I20: =SUM(I16:I19) -> 20000000 | J20: =SUM(J16:J19) -> 4040765 | L20: =L12 -> 0 | N20: =SUM(N8:N12)+SUM(N16:N19) -> 17886616 | O20: =SUM(O8:O12)+SUM(O16:O19) -> 1
B22: Price per Share
B23: Safe Price | N23: =Inputs!C13/(C8+C9+C10+C11+E16+E17+SidekickCapTable!D21) -> 4.1246319
B24: Series A Price | N24: =Inputs!C5/(C8+C9+C10+C11+E16+E17+SidekickCapTable!D21) -> 4.9495582
B25: Post-Money Valuation | N25: =Inputs!C5+Inputs!C6 -> 80000000

Sheet SeriesB
B1: SIDEKICK & 1011 VENTURES SERIES B
C4: Common | D4: Safe Preferred | G4: Option | I4: Series A Preferred | L4: Option | N4: Series B Preferred | Q4: Option | S4: Total Cap
C5: # of | D5: $ | E5: Safe Pref | G5: Pool + | I5: $ | J5: Series A | L5: Pool + | N5: $ | O5: Series B | Q5: Pool + | S5: Total FD | T5: %
C6: Shares | D6: Invested | E6: Shares | G6: Pre A | I6: Invested | J6: Shares | L6: Pre A | N6: Invested | O6: Shares | Q6: Pre B | S6: Shares | T6: FD
B7: Common Stock and Options:
B8: Brian Hazzard | C8: =SeriesA!C8 -> 3600000 | S8: =C8+E8+G8+J8+O8+Q8 -> 3600000 | T8: =S8/$S$23 -> 0.15598256
B9: David Wolpoff | C9: =SeriesA!C9 -> 3600000 | S9: =C9+E9+G9+J9+O9+Q9 -> 3600000 | T9: =S9/$S$23 -> 0.15598256
B10: Other Common Shareholders | C10: =SeriesA!C10 -> 1429687 | S10: =C10+E10+G10+J10+O10+Q10 -> 1429687 | T10: =S10/$S$23 -> 0.061946176
B11: ESOP Issued and Outstanding | C11: =SeriesA!C11 -> 1045471 | S11: =C11+E11+G11+J11+O11+Q11 -> 1045471 | T11: =S11/$S$23 -> 0.045298677
B12: ESOP Available (from Series A) | C12: =SeriesA!C12 -> 65105 | G12: =SeriesA!G12 -> 1723556.6 | S12: =C12+E12+G12+J12+O12+Q12 -> 1788661.6 | T12: =S12/$S$23 -> 0.0775
B13: ESOP Gross Top-Up (Series B) | Q13: =Inputs!C23*S23 -> 1615565.3 | S13: =C13+E13+G13+J13+O13+Q13 -> 1615565.3 | T13: =S13/$S$23 -> 0.07
B14: Total Common | C14: =SUM(C8:C13) -> 9740263 | G14: =G12 -> 1723556.6 | Q14: =Q13 -> 1615565.3 | S14: =SUM(S8:S13) -> 13079385 | T14: =S14/$S$23 -> 0.56670997
B16: Preferred Rounds
B17: Accomplice | D17: =SeriesA!D16 -> 8000000 | E17: =SeriesA!E16 -> 1939567 | I17: =SeriesA!I16 -> 5000000 | J17: =SeriesA!J16 -> 1010191 | N17: =Inputs!C22*(SeriesA!O16/(SeriesA!O16+SeriesA!O18+SeriesA!O19)) -> 7398647.8 | O17: =IFERROR(ROUND(N17/$S$26,0),0) -> 882245 | S17: =C17+E17+J17+O17 -> 3832003 | T17: =S17/$S$23 -> 0.1660349
B18: Other SAFE Investors | D18: =SeriesA!D17 -> 1825000 | E18: =SeriesA!E17 -> 442464 | S18: =C18+E18+J18+O18 -> 442464 | T18: =S18/$S$23 -> 0.019171296
B19: 1011 Ventures | I19: =SeriesA!I18 -> 12000000 | J19: =SeriesA!J18 -> 2424459 | N19: =Inputs!C22*(SeriesA!O18/(SeriesA!O16+SeriesA!O18+SeriesA!O19)) -> 6081081.3 | O19: =IFERROR(ROUND(N19/$S$26,0),0) -> 725133 | S19: =C19+E19+J19+O19 -> 3149592 | T19: =S19/$S$23 -> 0.13646706
B20: Other Series A Investors | I20: =SeriesA!I19 -> 3000000 | J20: =SeriesA!J19 -> 606115 | N20: =Inputs!C22*(SeriesA!O19/(SeriesA!O16+SeriesA!O18+SeriesA!O19)) -> 1520270.9 | O20: =IFERROR(ROUND(N20/$S$26,0),0) -> 181283 | S20: =C20+E20+J20+O20 -> 787398 | T20: =S20/$S$23 -> 0.034116765
B21: Other Series B Investors | N21: =Inputs!C21 -> 15000000 | O21: =IFERROR(ROUND(N21/$S$26,0),0) -> 1788662 | S21: =C21+E21+J21+O21 -> 1788662 | T21: =S21/$S$23 -> 0.07750002
B23: Totals | C23: =C14+SUM(C17:C21) -> 9740263 | D23: =SUM(D17:D21) -> 9825000 | E23: =SUM(E17:E21) -> 2382031 | G23: =G14 -> 1723556.6 | I23: =SUM(I17:I21) -> 20000000 | J23: =SUM(J17:J21) -> 4040765 | L23: =L12 -> 0 | N23: =SUM(N17:N21) -> 30000000 | O23: =SUM(O17:O21) -> 3577323 | Q23: =Q14 -> 1615565.3 | S23: =SUM(S8:S13)+SUM(S17:S21) -> 23079504 | T23: =SUM(T8:T13)+SUM(T17:T21) -> 1
B25: Price per Share
B26: Series B Price | S26: =Inputs!C19/SeriesA!N20 -> 8.3861589
B27: Post-Money Valuation | S27: =Inputs!C19+Inputs!C20 -> 180000000
B28: Safe Price (from Series A) | S28: =SeriesA!N23 -> 4.1246319
B29: Series A Price (from Series A) | S29: =SeriesA!N24 -> 4.9495582
