Workbook

Sheet SK Cap Table
A1: Shareholder | B1: Common Stock | C1: SAFE Amount | D1: Total Issued | E1: % Issued | F1: Options | G1: Total FDB | H1: % FDB
A2: Brian Hazzard | B2: 3600000 | D2: =B2 | E2: =D2/$D$37 | G2: =D2+F2 | H2: =G2/$G$37
A3: David Wolpoff | B3: 3600000 | D3: =B3 | E3: =D3/$D$37 | G3: =D3+F3 | H3: =G3/$G$37
A4: Ian Lee | B4: 222187 | D4: =B4 | E4: =D4/$D$37 | G4: =D4+F4 | H4: =G4/$G$37
A5: Kyle Haugsness | B5: 592500 | D5: =B5 | E5: =D5/$D$37 | G5: =D5+F5 | H5: =G5/$G$37
A6: Paul Riegle | B6: 592500 | D6: =B6 | E6: =D6/$D$37 | G6: =D6+F6 | H6: =G6/$G$37
A7: Chris Butts | B7: 112400 | C7: 25000 | D7: =B7 | E7: =D7/$D$37 | G7: =D7+F7 | H7: =G7/$G$37
A8: Maurice Granfield | B8: 9000 | C8: 25000 | D8: =B8 | E8: =D8/$D$37 | G8: =D8+F8 | H8: =G8/$G$37
A9: Pawan Lakshmanan | B9: 95000 | D9: =B9 | E9: =D9/$D$37 | G9: =D9+F9 | H9: =G9/$G$37
A10: Eric McIntyre | B10: 285000 | D10: =B10 | E10: =D10/$D$37 | G10: =D10+F10 | H10: =G10/$G$37
A11: Patrick Heath | B11: 50000 | D11: =B11 | E11: =D11/$D$37 | G11: =D11+F11 | H11: =G11/$G$37
A12: Chris Lord | B12: 285000 | D12: =B12 | E12: =D12/$D$37 | G12: =D12+F12 | H12: =G12/$G$37
A13: Bradly Matheson | B13: 12395 | D13: =B13 | E13: =D13/$D$37 | G13: =D13+F13 | H13: =G13/$G$37
A14: Cole Proctor | B14: 8333 | D14: =B14 | E14: =D14/$D$37 | G14: =D14+F14 | H14: =G14/$G$37
A15: Accomplice Founder Fund, L.P. | C15: 137170.75 | D15: =B15 | E15: =D15/$D$37 | G15: =D15+F15 | H15: =G15/$G$37
A16: Accomplice Fund IV, L.P | C16: 3846829.2 | D16: =B16 | E16: =D16/$D$37 | G16: =D16+F16 | H16: =G16/$G$37
A17: Amir Bagherzadeh | C17: 16566 | D17: =B17 | E17: =D17/$D$37 | G17: =D17+F17 | H17: =G17/$G$37
A18: Elizabeth A. Donaghey Irrevocable Trust 2016 | C18: 250000 | D18: =B18 | E18: =D18/$D$37 | G18: =D18+F18 | H18: =G18/$G$37
A19: Gunderson Partners | C19: 100000 | D19: =B19 | E19: =D19/$D$37 | G19: =D19+F19 | H19: =G19/$G$37
A20: Joe Arcadi | C20: 300000 | D20: =B20 | E20: =D20/$D$37 | G20: =D20+F20 | H20: =G20/$G$37
A21: Kamal Ravikant Capital, LP - E4 | C21: 37500 | D21: =B21 | E21: =D21/$D$37 | G21: =D21+F21 | H21: =G21/$G$37
A22: Maria Cirino | C22: 250000 | D22: =B22 | E22: =D22/$D$37 | G22: =D22+F22 | H22: =G22/$G$37
A23: Mike Viscuso | C23: 100000 | D23: =B23 | E23: =D23/$D$37 | G23: =D23+F23 | H23: =G23/$G$37
A24: Mozart Holdings, LLC | C24: 41164 | D24: =B24 | E24: =D24/$D$37 | G24: =D24+F24 | H24: =G24/$G$37
A25: Orcinus Generational Irrevocable Trust - 2024 | C25: 2328778 | D25: =B25 | E25: =D25/$D$37 | G25: =D25+F25 | H25: =G25/$G$37
A26: Owl Rock Capital III, LLC | C26: 1506000 | D26: =B26 | E26: =D26/$D$37 | G26: =D26+F26 | H26: =G26/$G$37
... A34: UWS West End Family Trust | C34: 250000 | D34: =B34 | E34: =D34/$D$37 | G34: =D34+F34 | H34: =G34/$G$37
A35: Allocated/Promised ESOP | D35: =B35+C35 | E35: =D35/$D$37 | F35: =B42 | G35: =D35+F35 | H35: =G35/$G$37
A36: Unallocated ESOP | D36: =B36+C36 | E36: =D36/$D$37 | F36: =B41 | G36: =D36+F36 | H36: =G36/$G$37
A37: Total: | B37: =SUM(B2:B36) | C37: =SUM(C2:C36) | D37: =SUM(D2:D36) | E37: =SUM(E2:E36) | F37: =SUM(F2:F36) | G37: =SUM(G2:G36) | H37: =SUM(H2:H36)
A39: ESOP
A40: Total Pool: | B40: 275948
A41: Unallocated: | B41: =B40-B42
A42: Allocated: | B42: 210843

Sheet SK Series A
B2: SIDEKICK & TEN ELEVEN SERIES A
C4: Common | D4: SAFE | G4: Option | I4: Series A | L4: Option | N4: Total Capitalization
C5: # of | D5: $ | E5: Converted | G5: Pool + | I5: $ | J5: Preferred | L5: Pool + | N5: Total FD | O5: % | Q5: %
C6: Shares | D6: Invested | E6: Shares | G6: Pre SAFE | I6: Invested | J6: Shares | L6: Pre A | N6: Shares | O6: FD | Q6: Preferred
B7: Common Stock and Options:
B8: ='SK Cap Table'!A2 | C8: ='SK Cap Table'!B2 | N8: =C8+E8+G8+J8+L8 | O8: =N8/$N$50
B9: ='SK Cap Table'!A3 | C9: ='SK Cap Table'!B3 | N9: =C9+E9+G9+J9+L9 | O9: =N9/$N$50
B10: ='SK Cap Table'!A4 | C10: ='SK Cap Table'!B4 | N10: =C10+E10+G10+J10+L10 | O10: =N10/$N$50
B11: ='SK Cap Table'!A5 | C11: ='SK Cap Table'!B5 | N11: =C11+E11+G11+J11+L11 | O11: =N11/$N$50
B12: ='SK Cap Table'!A6 | C12: ='SK Cap Table'!B6 | N12: =C12+E12+G12+J12+L12 | O12: =N12/$N$50
B13: ='SK Cap Table'!A7 | C13: ='SK Cap Table'!B7 | N13: =C13+E13+G13+J13+L13 | O13: =N13/$N$50
B14: ='SK Cap Table'!A8 | C14: ='SK Cap Table'!B8 | N14: =C14+E14+G14+J14+L14 | O14: =N14/$N$50
B15: ='SK Cap Table'!A9 | C15: ='SK Cap Table'!B9 | N15: =C15+E15+G15+J15+L15 | O15: =N15/$N$50
B16: ='SK Cap Table'!A10 | C16: ='SK Cap Table'!B10 | N16: =C16+E16+G16+J16+L16 | O16: =N16/$N$50
B17: ='SK Cap Table'!A11 | C17: ='SK Cap Table'!B11 | N17: =C17+E17+G17+J17+L17 | O17: =N17/$N$50
B18: ='SK Cap Table'!A12 | C18: ='SK Cap Table'!B12 | N18: =C18+E18+G18+J18+L18 | O18: =N18/$N$50
B19: ='SK Cap Table'!A13 | C19: ='SK Cap Table'!B13 | N19: =C19+E19+G19+J19+L19 | O19: =N19/$N$50
B20: ='SK Cap Table'!A14 | C20: ='SK Cap Table'!B14 | N20: =C20+E20+G20+J20+L20 | O20: =N20/$N$50
B21: ESOP Issued & Outstanding | C21: ='SK Cap Table'!F35 | N21: =C21+E21+G21+J21+L21 | O21: =N21/$N$50
B22: ESOP Available | G22: ='SK Cap Table'!F36 | L22: =MAX(ROUND(0.10*$N$50-C21-G22,0),0) | N22: =C22+E22+G22+J22+L22 | O22: =N22/$N$50
B23: Total Common | C23: =SUM(C8:C22) | D23: =SUM(D8:D22) | E23: =SUM(E8:E22) | G23: =SUM(G8:G22) | I23: =SUM(I8:I22) | J23: =SUM(J8:J22) | L23: =SUM(L8:L22) | N23: =SUM(N8:N22) | O23: =N23/$N$50
B25: Preferred Rounds
B26: ='SK Cap Table'!A15 | D26: ='SK Cap Table'!C15 | E26: =ROUND(D26/$E$52,0) | N26: =C26+E26+G26+J26+L26 | O26: =N26/$N$50 | Q26: =(E26+J26)/($E$50+$J$50)
B27: ='SK Cap Table'!A16 | D27: ='SK Cap Table'!C16 | E27: =ROUND(D27/$E$52,0) | N27: =C27+E27+G27+J27+L27 | O27: =N27/$N$50 | Q27: =(E27+J27)/($E$50+$J$50)
B28: ='SK Cap Table'!A17 | D28: ='SK Cap Table'!C17 | E28: =ROUND(D28/$E$52,0) | N28: =C28+E28+G28+J28+L28 | O28: =N28/$N$50 | Q28: =(E28+J28)/($E$50+$J$50)
B29: ='SK Cap Table'!A18 | D29: ='SK Cap Table'!C18 | E29: =ROUND(D29/$E$52,0) | N29: =C29+E29+G29+J29+L29 | O29: =N29/$N$50 | Q29: =(E29+J29)/($E$50+$J$50)
B30: ='SK Cap Table'!A19 | D30: ='SK Cap Table'!C19 | E30: =ROUND(D30/$E$52,0) | N30: =C30+E30+G30+J30+L30 | O30: =N30/$N$50 | Q30: =(E30+J30)/($E$50+$J$50)
B31: ='SK Cap Table'!A20 | D31: ='SK Cap Table'!C20 | E31: =ROUND(D31/$E$52,0) | N31: =C31+E31+G31+J31+L31 | O31: =N31/$N$50 | Q31: =(E31+J31)/($E$50+$J$50)
B32: ='SK Cap Table'!A21 | D32: ='SK Cap Table'!C21 | E32: =ROUND(D32/$E$52,0) | N32: =C32+E32+G32+J32+L32 | O32: =N32/$N$50 | Q32: =(E32+J32)/($E$50+$J$50)
B33: ='SK Cap Table'!A22 | D33: ='SK Cap Table'!C22 | E33: =ROUND(D33/$E$52,0) | N33: =C33+E33+G33+J33+L33 | O33: =N33/$N$50 | Q33: =(E33+J33)/($E$50+$J$50)
B34: ='SK Cap Table'!A23 | D34: ='SK Cap Table'!C23 | E34: =ROUND(D34/$E$52,0) | N34: =C34+E34+G34+J34+L34 | O34: =N34/$N$50 | Q34: =(E34+J34)/($E$50+$J$50)
B35: ='SK Cap Table'!A24 | D35: ='SK Cap Table'!C24 | E35: =ROUND(D35/$E$52,0) | N35: =C35+E35+G35+J35+L35 | O35: =N35/$N$50 | Q35: =(E35+J35)/($E$50+$J$50)
B36: ='SK Cap Table'!A25 | D36: ='SK Cap Table'!C25 | E36: =ROUND(D36/$E$52,0) | N36: =C36+E36+G36+J36+L36 | O36: =N36/$N$50 | Q36: =(E36+J36)/($E$50+$J$50)
B37: ='SK Cap Table'!A26 | D37: ='SK Cap Table'!C26 | E37: =ROUND(D37/$E$52,0) | N37: =C37+E37+G37+J37+L37 | O37: =N37/$N$50 | Q37: =(E37+J37)/($E$50+$J$50)
... B45: ='SK Cap Table'!A34 | D45: ='SK Cap Table'!C34 | E45: =ROUND(D45/$E$52,0) | N45: =C45+E45+G45+J45+L45 | O45: =N45/$N$50 | Q45: =(E45+J45)/($E$50+$J$50)
B46: Ten Eleven | I46: 12000000 | J46: =ROUND($I$46/$J$52,0) | N46: =C46+E46+G46+J46+L46 | O46: =N46/$N$50 | Q46: =(E46+J46)/($E$50+$J$50)
B47: Accomplice | I47: 5000000 | J47: =ROUND($I$47/$J$52,0) | N47: =C47+E47+G47+J47+L47 | O47: =N47/$N$50 | Q47: =(E47+J47)/($E$50+$J$50)
B48: Other Series A Investors | I48: 3000000 | J48: =ROUND($I$48/$J$52,0) | N48: =C48+E48+G48+J48+L48 | O48: =N48/$N$50 | Q48: =(E48+J48)/($E$50+$J$50)
B50: Totals | C50: =C23+SUM(C26:C48) | D50: =SUM(D8:D49) | E50: =SUM(E8:E49) | G50: =SUM(G8:G49) | I50: =SUM(I8:I49) | J50: =SUM(J8:J49) | L50: =SUM(L8:L49) | N50: =N23+SUM(N26:N48) | O50: =SUM(O8:O49)
B52: Price per Share | E52: =$C$64/($N$50-$J$50-$L$50) | J52: =$J$54/$N$50
...

Sheet SK Series B
B2: SIDEKICK & TEN ELEVEN SERIES B
C4: Common | D4: SAFE | G4: Option | I4: Series A | L4: Option | N4: Series B | Q4: Option | S4: Total Capitalization
C5: # of | D5: $ | E5: Converted | G5: Pool + | I5: $ | J5: Preferred | L5: Pool + | N5: $ | O5: Preferred | Q5: Pool + | S5: Total FD | T5: % | V5: %
C6: Shares | D6: Invested | E6: Shares | G6: Pre SAFE | I6: Invested | J6: Shares | L6: Pre A | N6: Invested | O6: Shares | Q6: Pre B | S6: Shares | T6: FD | V6: Preferred
B7: Common Stock and Options:
B8: =+'SK Series A'!B8 | C8: =+'SK Series A'!C8 | D8: =+'SK Series A'!D8 | E8: =+'SK Series A'!E8 | G8: =+'SK Series A'!G8 | I8: =+'SK Series A'!I8 | J8: =+'SK Series A'!J8 | L8: =+'SK Series A'!L8 | S8: =C8+E8+G8+J8+L8+O8+Q8 | T8: =S8/$S$51 | V8: =IFERROR((E8+J8+O8)/($E$51+$J$51+$O$51),0)
B9: =+'SK Series A'!B9 | C9: =+'SK Series A'!C9 | D9: =+'SK Series A'!D9 | E9: =+'SK Series A'!E9 | G9: =+'SK Series A'!G9 | I9: =+'SK Series A'!I9 | J9: =+'SK Series A'!J9 | L9: =+'SK Series A'!L9 | S9: =C9+E9+G9+J9+L9+O9+Q9 | T9: =S9/$S$51 | V9: =IFERROR((E9+J9+O9)/($E$51+$J$51+$O$51),0)
B10: =+'SK Series A'!B10 | C10: =+'SK Series A'!C10 | D10: =+'SK Series A'!D10 | E10: =+'SK Series A'!E10 | G10: =+'SK Series A'!G10 | I10: =+'SK Series A'!I10 | J10: =+'SK Series A'!J10 | L10: =+'SK Series A'!L10 | S10: =C10+E10+G10+J10+L10+O10+Q10 | T10: =S10/$S$51 | V10: =IFERROR((E10+J10+O10)/($E$51+$J$51+$O$51),0)
B11: =+'SK Series A'!B11 | C11: =+'SK Series A'!C11 | D11: =+'SK Series A'!D11 | E11: =+'SK Series A'!E11 | G11: =+'SK Series A'!G11 | I11: =+'SK Series A'!I11 | J11: =+'SK Series A'!J11 | L11: =+'SK Series A'!L11 | S11: =C11+E11+G11+J11+L11+O11+Q11 | T11: =S11/$S$51 | V11: =IFERROR((E11+J11+O11)/($E$51+$J$51+$O$51),0)
B12: =+'SK Series A'!B12 | C12: =+'SK Series A'!C12 | D12: =+'SK Series A'!D12 | E12: =+'SK Series A'!E12 | G12: =+'SK Series A'!G12 | I12: =+'SK Series A'!I12 | J12: =+'SK Series A'!J12 | L12: =+'SK Series A'!L12 | S12: =C12+E12+G12+J12+L12+O12+Q12 | T12: =S12/$S$51 | V12: =IFERROR((E12+J12+O12)/($E$51+$J$51+$O$51),0)
B13: =+'SK Series A'!B13 | C13: =+'SK Series A'!C13 | D13: =+'SK Series A'!D13 | E13: =+'SK Series A'!E13 | G13: =+'SK Series A'!G13 | I13: =+'SK Series A'!I13 | J13: =+'SK Series A'!J13 | L13: =+'SK Series A'!L13 | S13: =C13+E13+G13+J13+L13+O13+Q13 | T13: =S13/$S$51 | V13: =IFERROR((E13+J13+O13)/($E$51+$J$51+$O$51),0)
B14: =+'SK Series A'!B14 | C14: =+'SK Series A'!C14 | D14: =+'SK Series A'!D14 | E14: =+'SK Series A'!E14 | G14: =+'SK Series A'!G14 | I14: =+'SK Series A'!I14 | J14: =+'SK Series A'!J14 | L14: =+'SK Series A'!L14 | S14: =C14+E14+G14+J14+L14+O14+Q14 | T14: =S14/$S$51 | V14: =IFERROR((E14+J14+O14)/($E$51+$J$51+$O$51),0)
B15: =+'SK Series A'!B15 | C15: =+'SK Series A'!C15 | D15: =+'SK Series A'!D15 | E15: =+'SK Series A'!E15 | G15: =+'SK Series A'!G15 | I15: =+'SK Series A'!I15 | J15: =+'SK Series A'!J15 | L15: =+'SK Series A'!L15 | S15: =C15+E15+G15+J15+L15+O15+Q15 | T15: =S15/$S$51 | V15: =IFERROR((E15+J15+O15)/($E$51+$J$51+$O$51),0)
B16: =+'SK Series A'!B16 | C16: =+'SK Series A'!C16 | D16: =+'SK Series A'!D16 | E16: =+'SK Series A'!E16 | G16: =+'SK Series A'!G16 | I16: =+'SK Series A'!I16 | J16: =+'SK Series A'!J16 | L16: =+'SK Series A'!L16 | S16: =C16+E16+G16+J16+L16+O16+Q16 | T16: =S16/$S$51 | V16: =IFERROR((E16+J16+O16)/($E$51+$J$51+$O$51),0)
B17: =+'SK Series A'!B17 | C17: =+'SK Series A'!C17 | D17: =+'SK Series A'!D17 | E17: =+'SK Series A'!E17 | G17: =+'SK Series A'!G17 | I17: =+'SK Series A'!I17 | J17: =+'SK Series A'!J17 | L17: =+'SK Series A'!L17 | S17: =C17+E17+G17+J17+L17+O17+Q17 | T17: =S17/$S$51 | V17: =IFERROR((E17+J17+O17)/($E$51+$J$51+$O$51),0)
B18: =+'SK Series A'!B18 | C18: =+'SK Series A'!C18 | D18: =+'SK Series A'!D18 | E18: =+'SK Series A'!E18 | G18: =+'SK Series A'!G18 | I18: =+'SK Series A'!I18 | J18: =+'SK Series A'!J18 | L18: =+'SK Series A'!L18 | S18: =C18+E18+G18+J18+L18+O18+Q18 | T18: =S18/$S$51 | V18: =IFERROR((E18+J18+O18)/($E$51+$J$51+$O$51),0)
B19: =+'SK Series A'!B19 | C19: =+'SK Series A'!C19 | D19: =+'SK Series A'!D19 | E19: =+'SK Series A'!E19 | G19: =+'SK Series A'!G19 | I19: =+'SK Series A'!I19 | J19: =+'SK Series A'!J19 | L19: =+'SK Series A'!L19 | S19: =C19+E19+G19+J19+L19+O19+Q19 | T19: =S19/$S$51 | V19: =IFERROR((E19+J19+O19)/($E$51+$J$51+$O$51),0)
B20: =+'SK Series A'!B20 | C20: =+'SK Series A'!C20 | D20: =+'SK Series A'!D20 | E20: =+'SK Series A'!E20 | G20: =+'SK Series A'!G20 | I20: =+'SK Series A'!I20 | J20: =+'SK Series A'!J20 | L20: =+'SK Series A'!L20 | S20: =C20+E20+G20+J20+L20+O20+Q20 | T20: =S20/$S$51 | V20: =IFERROR((E20+J20+O20)/($E$51+$J$51+$O$51),0)
B21: =+'SK Series A'!B21 | C21: =+'SK Series A'!C21 | D21: =+'SK Series A'!D21 | E21: =+'SK Series A'!E21 | G21: =+'SK Series A'!G21 | I21: =+'SK Series A'!I21 | J21: =+'SK Series A'!J21 | K21: =+'SK Series A'!K21 | L21: =+'SK Series A'!L21 | S21: =C21+E21+G21+J21+L21+O21+Q21 | T21: =S21/$S$51 | V21: =IFERROR((E21+J21+O21)/($E$51+$J$51+$O$51),0)
B22: =+'SK Series A'!B22 | G22: =+'SK Series A'!G22 | L22: =+'SK Series A'!L22 | Q22: =MAX(ROUND($S$51*$C$65-('SK Series A'!C21+'SK Series A'!G22+'SK Series A'!L22),0),0) | S22: =C22+E22+G22+J22+L22+O22+Q22 | T22: =S22/$S$51 | V22: =IFERROR((E22+J22+O22)/($E$51+$J$51+$O$51),0)
B23: Total Common | C23: =SUM(C8:C22) | D23: =SUM(D8:D22) | E23: =SUM(E8:E22) | G23: =SUM(G8:G22) | I23: =SUM(I8:I22) | J23: =SUM(J8:J22) | L23: =SUM(L8:L22) | N23: =SUM(N8:N22) | O23: =SUM(O8:O22) | Q23: =SUM(Q8:Q22) | S23: =SUM(S8:S22) | T23: =S23/$S$51 | V23: =IFERROR((E23+J23+O23)/($E$51+$J$51+$O$51),0)
B25: Preferred Rounds
B26: =+'SK Series A'!B26 | C26: =+'SK Series A'!C26 | D26: =+'SK Series A'!D26 | E26: =+'SK Series A'!E26 | G26: =+'SK Series A'!G26 | I26: =+'SK Series A'!I26 | J26: =+'SK Series A'!J26 | L26: =+'SK Series A'!L26 | N26: =($C$62-15000000)*'SK Series A'!Q26 | O26: =ROUND(N26/$O$53,0) | S26: =C26+E26+G26+J26+L26+O26+Q26 | T26: =S26/$S$51 | V26: =IFERROR((E26+J26+O26)/($E$51+$J$51+$O$51),0)
B27: =+'SK Series A'!B27 | C27: =+'SK Series A'!C27 | D27: =+'SK Series A'!D27 | E27: =+'SK Series A'!E27 | G27: =+'SK Series A'!G27 | I27: =+'SK Series A'!I27 | J27: =+'SK Series A'!J27 | L27: =+'SK Series A'!L27 | N27: =($C$62-15000000)*'SK Series A'!Q27 | O27: =ROUND(N27/$O$53,0) | S27: =C27+E27+G27+J27+L27+O27+Q27 | T27: =S27/$S$51 | V27: =IFERROR((E27+J27+O27)/($E$51+$J$51+$O$51),0)
B28: =+'SK Series A'!B28 | C28: =+'SK Series A'!C28 | D28: =+'SK Series A'!D28 | E28: =+'SK Series A'!E28 | G28: =+'SK Series A'!G28 | I28: =+'SK Series A'!I28 | J28: =+'SK Series A'!J28 | L28: =+'SK Series A'!L28 | N28: =($C$62-15000000)*'SK Series A'!Q28 | O28: =ROUND(N28/$O$53,0) | S28: =C28+E28+G28+J28+L28+O28+Q28 | T28: =S28/$S$51 | V28: =IFERROR((E28+J28+O28)/($E$51+$J$51+$O$51),0)
B29: =+'SK Series A'!B29 | C29: =+'SK Series A'!C29 | D29: =+'SK Series A'!D29 | E29: =+'SK Series A'!E29 | G29: =+'SK Series A'!G29 | I29: =+'SK Series A'!I29 | J29: =+'SK Series A'!J29 | L29: =+'SK Series A'!L29 | N29: =($C$62-15000000)*'SK Series A'!Q29 | O29: =ROUND(N29/$O$53,0) | S29: =C29+E29+G29+J29+L29+O29+Q29 | T29: =S29/$S$51 | V29: =IFERROR((E29+J29+O29)/($E$51+$J$51+$O$51),0)
B30: =+'SK Series A'!B30 | C30: =+'SK Series A'!C30 | D30: =+'SK Series A'!D30 | E30: =+'SK Series A'!E30 | G30: =+'SK Series A'!G30 | I30: =+'SK Series A'!I30 | J30: =+'SK Series A'!J30 | L30: =+'SK Series A'!L30 | N30: =($C$62-15000000)*'SK Series A'!Q30 | O30: =ROUND(N30/$O$53,0) | S30: =C30+E30+G30+J30+L30+O30+Q30 | T30: =S30/$S$51 | V30: =IFERROR((E30+J30+O30)/($E$51+$J$51+$O$51),0)
B31: =+'SK Series A'!B31 | C31: =+'SK Series A'!C31 | D31: =+'SK Series A'!D31 | E31: =+'SK Series A'!E31 | G31: =+'SK Series A'!G31 | I31: =+'SK Series A'!I31 | J31: =+'SK Series A'!J31 | L31: =+'SK Series A'!L31 | N31: =($C$62-15000000)*'SK Series A'!Q31 | O31: =ROUND(N31/$O$53,0) | S31: =C31+E31+G31+J31+L31+O31+Q31 | T31: =S31/$S$51 | V31: =IFERROR((E31+J31+O31)/($E$51+$J$51+$O$51),0)
B32: =+'SK Series A'!B32 | C32: =+'SK Series A'!C32 | D32: =+'SK Series A'!D32 | E32: =+'SK Series A'!E32 | G32: =+'SK Series A'!G32 | I32: =+'SK Series A'!I32 | J32: =+'SK Series A'!J32 | L32: =+'SK Series A'!L32 | N32: =($C$62-15000000)*'SK Series A'!Q32 | O32: =ROUND(N32/$O$53,0) | S32: =C32+E32+G32+J32+L32+O32+Q32 | T32: =S32/$S$51 | V32: =IFERROR((E32+J32+O32)/($E$51+$J$51+$O$51),0)
B33: =+'SK Series A'!B33 | C33: =+'SK Series A'!C33 | D33: =+'SK Series A'!D33 | E33: =+'SK Series A'!E33 | G33: =+'SK Series A'!G33 | I33: =+'SK Series A'!I33 | J33: =+'SK Series A'!J33 | L33: =+'SK Series A'!L33 | N33: =($C$62-15000000)*'SK Series A'!Q33 | O33: =ROUND(N33/$O$53,0) | S33: =C33+E33+G33+J33+L33+O33+Q33 | T33: =S33/$S$51 | V33: =IFERROR((E33+J33+O33)/($E$51+$J$51+$O$51),0)
B34: =+'SK Series A'!B34 | C34: =+'SK Series A'!C34 | D34: =+'SK Series A'!D34 | E34: =+'SK Series A'!E34 | G34: =+'SK Series A'!G34 | I34: =+'SK Series A'!I34 | J34: =+'SK Series A'!J34 | L34: =+'SK Series A'!L34 | N34: =($C$62-15000000)*'SK Series A'!Q34 | O34: =ROUND(N34/$O$53,0) | S34: =C34+E34+G34+J34+L34+O34+Q34 | T34: =S34/$S$51 | V34: =IFERROR((E34+J34+O34)/($E$51+$J$51+$O$51),0)
B35: =+'SK Series A'!B35 | C35: =+'SK Series A'!C35 | D35: =+'SK Series A'!D35 | E35: =+'SK Series A'!E35 | G35: =+'SK Series A'!G35 | I35: =+'SK Series A'!I35 | J35: =+'SK Series A'!J35 | L35: =+'SK Series A'!L35 | N35: =($C$62-15000000)*'SK Series A'!Q35 | O35: =ROUND(N35/$O$53,0) | S35: =C35+E35+G35+J35+L35+O35+Q35 | T35: =S35/$S$51 | V35: =IFERROR((E35+J35+O35)/($E$51+$J$51+$O$51),0)
B36: =+'SK Series A'!B36 | C36: =+'SK Series A'!C36 | D36: =+'SK Series A'!D36 | E36: =+'SK Series A'!E36 | G36: =+'SK Series A'!G36 | I36: =+'SK Series A'!I36 | J36: =+'SK Series A'!J36 | L36: =+'SK Series A'!L36 | N36: =($C$62-15000000)*'SK Series A'!Q36 | O36: =ROUND(N36/$O$53,0) | S36: =C36+E36+G36+J36+L36+O36+Q36 | T36: =S36/$S$51 | V36: =IFERROR((E36+J36+O36)/($E$51+$J$51+$O$51),0)
B37: =+'SK Series A'!B37 | C37: =+'SK Series A'!C37 | D37: =+'SK Series A'!D37 | E37: =+'SK Series A'!E37 | G37: =+'SK Series A'!G37 | I37: =+'SK Series A'!I37 | J37: =+'SK Series A'!J37 | L37: =+'SK Series A'!L37 | N37: =($C$62-15000000)*'SK Series A'!Q37 | O37: =ROUND(N37/$O$53,0) | S37: =C37+E37+G37+J37+L37+O37+Q37 | T37: =S37/$S$51 | V37: =IFERROR((E37+J37+O37)/($E$51+$J$51+$O$51),0)
... B45: =+'SK Series A'!B45 | C45: =+'SK Series A'!C45 | D45: =+'SK Series A'!D45 | E45: =+'SK Series A'!E45 | G45: =+'SK Series A'!G45 | I45: =+'SK Series A'!I45 | J45: =+'SK Series A'!J45 | L45: =+'SK Series A'!L45 | N45: =($C$62-15000000)*'SK Series A'!Q45 | O45: =ROUND(N45/$O$53,0) | S45: =C45+E45+G45+J45+L45+O45+Q45 | T45: =S45/$S$51 | V45: =IFERROR((E45+J45+O45)/($E$51+$J$51+$O$51),0)
B46: =+'SK Series A'!B46 | C46: =+'SK Series A'!C46 | D46: =+'SK Series A'!D46 | E46: =+'SK Series A'!E46 | G46: =+'SK Series A'!G46 | I46: =+'SK Series A'!I46 | J46: =+'SK Series A'!J46 | K46: =+'SK Series A'!K46 | L46: =+'SK Series A'!L46 | N46: =($C$62-15000000)*'SK Series A'!Q46 | O46: =ROUND(N46/$O$53,0) | S46: =C46+E46+G46+J46+L46+O46+Q46 | T46: =S46/$S$51 | V46: =IFERROR((E46+J46+O46)/($E$51+$J$51+$O$51),0)
B47: =+'SK Series A'!B47 | C47: =+'SK Series A'!C47 | D47: =+'SK Series A'!D47 | E47: =+'SK Series A'!E47 | G47: =+'SK Series A'!G47 | I47: =+'SK Series A'!I47 | J47: =+'SK Series A'!J47 | K47: =+'SK Series A'!K47 | L47: =+'SK Series A'!L47 | N47: =($C$62-15000000)*'SK Series A'!Q47 | O47: =ROUND(N47/$O$53,0) | S47: =C47+E47+G47+J47+L47+O47+Q47 | T47: =S47/$S$51 | V47: =IFERROR((E47+J47+O47)/($E$51+$J$51+$O$51),0)
B48: =+'SK Series A'!B48 | C48: =+'SK Series A'!C48 | D48: =+'SK Series A'!D48 | E48: =+'SK Series A'!E48 | G48: =+'SK Series A'!G48 | I48: =+'SK Series A'!I48 | J48: =+'SK Series A'!J48 | K48: =+'SK Series A'!K48 | L48: =+'SK Series A'!L48 | N48: =($C$62-15000000)*'SK Series A'!Q48 | O48: =ROUND(N48/$O$53,0) | S48: =C48+E48+G48+J48+L48+O48+Q48 | T48: =S48/$S$51 | V48: =IFERROR((E48+J48+O48)/($E$51+$J$51+$O$51),0)
B49: Other Series B Investor | N49: 15000000 | O49: =ROUND(N49/$O$53,0) | S49: =C49+E49+G49+J49+L49+O49+Q49 | T49: =S49/$S$51 | V49: =IFERROR((E49+J49+O49)/($E$51+$J$51+$O$51),0)
B51: Totals | C51: =C23+SUM(C26:C49) | D51: =SUM(D8:D49) | E51: =SUM(E8:E49) | G51: =SUM(G8:G49) | I51: =SUM(I8:I49) | J51: =SUM(J8:J49) | L51: =SUM(L8:L49) | N51: =SUM(N8:N49) | O51: =SUM(O8:O49) | Q51: =SUM(Q8:Q49) | S51: =S23+SUM(S26:S49) | T51: =SUM(T8:T49) | V51: =SUM(V26:V49)
...
